[10 May 23 12:35:55] : django.request - ERROR - Internal Server Error: /api/PreAuth/EnhancementPost
Traceback (most recent call last):
  File "D:\Claim Assurance\.env\lib\site-packages\django\core\handlers\exception.py", line 55, in inner
    response = get_response(request)
  File "D:\Claim Assurance\.env\lib\site-packages\django\core\handlers\base.py", line 197, in _get_response
    response = wrapped_callback(request, *callback_args, **callback_kwargs)
  File "D:\Claim Assurance\.env\lib\site-packages\django\views\decorators\csrf.py", line 54, in wrapped_view
    return view_func(*args, **kwargs)
  File "D:\Claim Assurance\.env\lib\site-packages\django\views\generic\base.py", line 103, in view
    return self.dispatch(request, *args, **kwargs)
  File "D:\Claim Assurance\.env\lib\site-packages\rest_framework\views.py", line 511, in dispatch
    self.response = self.finalize_response(request, response, *args, **kwargs)
  File "D:\Claim Assurance\.env\lib\site-packages\rest_framework\views.py", line 423, in finalize_response
    assert isinstance(response, HttpResponseBase), (
AssertionError: Expected a `Response`, `HttpResponse` or `HttpStreamingResponse` to be returned from the view, but received a `<class 'NoneType'>`
[10 May 23 12:35:55] : django.server - ERROR - "POST /api/PreAuth/EnhancementPost HTTP/1.1" 500 19243
[10 May 23 12:38:05] : django.request - ERROR - Internal Server Error: /api/PreAuth/EnhancementPost
Traceback (most recent call last):
  File "D:\Claim Assurance\.env\lib\site-packages\django\core\handlers\exception.py", line 55, in inner
    response = get_response(request)
  File "D:\Claim Assurance\.env\lib\site-packages\django\core\handlers\base.py", line 197, in _get_response
    response = wrapped_callback(request, *callback_args, **callback_kwargs)
  File "D:\Claim Assurance\.env\lib\site-packages\django\views\decorators\csrf.py", line 54, in wrapped_view
    return view_func(*args, **kwargs)
  File "D:\Claim Assurance\.env\lib\site-packages\django\views\generic\base.py", line 103, in view
    return self.dispatch(request, *args, **kwargs)
  File "D:\Claim Assurance\.env\lib\site-packages\rest_framework\views.py", line 511, in dispatch
    self.response = self.finalize_response(request, response, *args, **kwargs)
  File "D:\Claim Assurance\.env\lib\site-packages\rest_framework\views.py", line 423, in finalize_response
    assert isinstance(response, HttpResponseBase), (
AssertionError: Expected a `Response`, `HttpResponse` or `HttpStreamingResponse` to be returned from the view, but received a `<class 'NoneType'>`
[10 May 23 12:38:08] : django.server - ERROR - "POST /api/PreAuth/EnhancementPost HTTP/1.1" 500 19259
[10 May 23 12:47:45] : claimAssure - ERROR - error occured
Traceback (most recent call last):
  File "D:\Claim Assurance\PreAuth\views.py", line 712, in post
    raise Exception
Exception
[10 May 23 12:52:30] : claimAssure - ERROR - error occured in /api/PreAuth/EnhancementPost
Traceback (most recent call last):
  File "D:\Claim Assurance\PreAuth\views.py", line 712, in post
    raise Exception
Exception
[11 May 23 17:14:21] : claimAssure - ERROR - Unable to read field PRE004 on the server
[11 May 23 17:16:37] : claimAssure - ERROR - Unable to read field PRE004 on the server
